Workbook
Name Print_Area: 'MEDIÇÃO 39'!$A$1:$Q$292
Name Print_Titles: 'MEDIÇÃO 39'!$1:$14

Sheet MEDIÇÃO 39
B1: BOLETIM DE MEDIÇÃO Nº 39
B2: Nº 174/PMI-SEINFRA/2023 | C2: MANUTENÇÃO DA ILUMINAÇÃO PÚBLICA
A4: INÍCIO DO CONTRATO | B4: CONTRATO NATUREZA CONTINUA | C4: EMPRESA CONTRATADA | N4: PERIODO DE MEDIÇÃO | O4: TOMADOR/AG. PROMOTOR OU TOMADOR
N5: 01/04/2026 A 30/04/2026 | O5: SECRETARIA DE INFRAESTRUTURA E OBRAS
A6: 45108 | B6: CT - DATA DA ASSINATURA | C6: EIP SERVIÇOS DE ILUMINAÇÃO LTDA | N6: VALOR DA MEDIÇÃO
A7: VALOR PREVISTO | B7: 45103 | C7: OBJETO DO CTEF (RESUMIDO) | N7: =N292 -> #REF! | O7: AGENTE FINANCEIRO OU AG. OPERADOR REPASSE
A8: 5814300.9 | O8: FUNDO MUNICIPAL DE ILUMINAÇÃO PÚBLICA
A9: VALOR 1º + 2º TERMO ADT + APOSTILAMENTO | B9: 45348 | C9: CONTRATAÇÃO DE EMPRESA DE ENGENHARIA PARA PRESTAÇÃO DOS SERVIÇOS DE MANUTENÇÃO DE CARÁTER PREVENTIVO E CORRETIVO NO PARQUE DE ILUMINAÇÃO PÚBLICA DO MUNICÍPIO DE IPOJUCA - PE | N9: SALDO CONTRATUAL
A10: =771088.5+632153.17+294797.54 -> 1698039.2 | C10: LOCAL DA OBRA (BAIRRO / MUNICIPIO / UF) | N10: =$A$12-O292 -> #REF!
A11: VALOR TOTAL
A12: =SUM(A8,A10) -> 7512340.1 | C12: IPOJUCA - PE
A13: ITEM | B13: DESCRIÇÃO | C13: UNID. | D13: QUANT. PREVISTO | E13: 1º TERMO ADITIVO | F13: 2º TERMO ADITIVO | G13: QUANT. TOTAL | H13: PREÇO UNITÁRIO | I13: EXECUTADO FISICO (QUANTIDADE) | M13: EXECUTADO FINANCEIRO (R$)
I14: SOMA DOS BM's | J14: MEDIDO NO PERIODO | K14: ACUMULADO INCLUINDO O PERIODO ATUAL | L14: SALDO A EXECUTAR | M14: ACUMULADO ATÉ O PERIODO ANTERIOR | N14: MEDIDO NO PERIODO | O14: ACUMULADO INCLUINDO O PERIODO ATUAL | P14: SALDO A EXECUTAR | Q14: DESVIO (%)
A15: 1.0 | B15: SERVIÇOS DE MANUTENÇÃO DO SISTEMA DE ILUMINAÇÃO PÚBLICA
A16: 1.1 | B16: GESTÃO E MANUTENÇÃO DAS UNIDADES CONSUMIDORAS, CLASSIFICADAS COMO ILUMINAÇÃO PÚBLICA - PREÇO UNITÁRIO POR PONTO LUMINOSO. | C16: UN | D16: 105360 | G16: =SUM(D16:F16) -> 105360 | H16: =VLOOKUP(A16,#REF!,5,0) -> #REF! | I16: =SUM(#REF!) -> #REF! | J16: =SUMIF(#REF!,'MEDIÇÃO 39'!A16,#REF!) -> #REF! | K16: =I16+J16 -> #REF! | L16: =G16-K16 -> #REF! | M16: =ROUND(I16*H16,2) -> #REF! | N16: =ROUND(J16*H16,2) -> #REF! | O16: =ROUND(M16+N16,2) -> #REF! | P16: =ROUND((G16*H16)-O16,2) -> #REF! | Q16: =IFERROR(ROUND(O16/(G16*H16),2),0) -> 0
A17: 2.0 | B17: SERVIÇOS DE GESTÃO DO SISTEMA DE ILUMINAÇÃO PÚBLICA
A18: 2.1 | B18: ABERTURA DE CAVA EM TERRENO NORMAL | C18: UN | D18: 25 | G18: =SUM(D18:F18) -> 25 | H18: =VLOOKUP(A18,#REF!,5,0) -> #REF! | I18: =SUM(#REF!) -> #REF! | J18: =SUMIF(#REF!,'MEDIÇÃO 39'!A18,#REF!) -> #REF! | K18: =I18+J18 -> #REF! | L18: =G18-K18 -> #REF! | M18: =ROUND(I18*H18,2) -> #REF! | N18: =ROUND(J18*H18,2) -> #REF! | O18: =ROUND(M18+N18,2) -> #REF! | P18: =ROUND((G18*H18)-O18,2) -> #REF! | Q18: =IFERROR(ROUND(O18/(G18*H18),2),0) -> 0
A19: 2.2 | B19: ABERTURA E FECHAMENTO DE VALA, LARGURA 40CM E PROFUNDIDADE 60 CM | C19: UN | D19: 250 | G19: =SUM(D19:F19) -> 250 | H19: =VLOOKUP(A19,#REF!,5,0) -> #REF! | I19: =SUM(#REF!) -> #REF! | J19: =SUMIF(#REF!,'MEDIÇÃO 39'!A19,#REF!) -> #REF! | K19: =I19+J19 -> #REF! | L19: =G19-K19 -> #REF! | M19: =ROUND(I19*H19,2) -> #REF! | N19: =ROUND(J19*H19,2) -> #REF! | O19: =ROUND(M19+N19,2) -> #REF! | P19: =ROUND((G19*H19)-O19,2) -> #REF! | Q19: =IFERROR(ROUND(O19/(G19*H19),2),0) -> 0
A20: 2.3 | B20: CADASTRO DE PONTO DE ILUMINAÇÃO PÚBLICA COM GEORREFERENCIAMENTO | C20: UN | D20: 1756 | G20: =SUM(D20:F20) -> 1756 | H20: =VLOOKUP(A20,#REF!,5,0) -> #REF! | I20: =SUM(#REF!) -> #REF! | J20: =SUMIF(#REF!,'MEDIÇÃO 39'!A20,#REF!) -> #REF! | K20: =I20+J20 -> #REF! | L20: =G20-K20 -> #REF! | M20: =ROUND(I20*H20,2) -> #REF! | N20: =ROUND(J20*H20,2) -> #REF! | O20: =ROUND(M20+N20,2) -> #REF! | P20: =ROUND((G20*H20)-O20,2) -> #REF! | Q20: =IFERROR(ROUND(O20/(G20*H20),2),0) -> 0
A21: 2.4 | B21: CONCRETAGEM DE DUTOS OU CABOS | C21: M | D21: 50 | G21: =SUM(D21:F21) -> 50 | H21: =VLOOKUP(A21,#REF!,5,0) -> #REF! | I21: =SUM(#REF!) -> #REF! | J21: =SUMIF(#REF!,'MEDIÇÃO 39'!A21,#REF!) -> #REF! | K21: =I21+J21 -> #REF! | L21: =G21-K21 -> #REF! | M21: =ROUND(I21*H21,2) -> #REF! | N21: =ROUND(J21*H21,2) -> #REF! | O21: =ROUND(M21+N21,2) -> #REF! | P21: =ROUND((G21*H21)-O21,2) -> #REF! | Q21: =IFERROR(ROUND(O21/(G21*H21),2),0) -> 0
A22: 2.5 | B22: DESCARTE DE LÂMPADAS DE ACORDO COM A LEGISLTAÇÃO AMBIENTAL VIGENTE | C22: UN | D22: 585 | G22: =SUM(D22:F22) -> 585 | H22: =VLOOKUP(A22,#REF!,5,0) -> #REF! | I22: =SUM(#REF!) -> #REF! | J22: =SUMIF(#REF!,'MEDIÇÃO 39'!A22,#REF!) -> #REF! | K22: =I22+J22 -> #REF! | L22: =G22-K22 -> #REF! | M22: =ROUND(I22*H22,2) -> #REF! | N22: =ROUND(J22*H22,2) -> #REF! | O22: =ROUND(M22+N22,2) -> #REF! | P22: =ROUND((G22*H22)-O22,2) -> #REF! | Q22: =IFERROR(ROUND(O22/(G22*H22),2),0) -> 0
A23: 2.6 | B23: EXECUÇÃO DE ATERRAMENTO SIMPLES | C23: UN | D23: 5 | G23: =SUM(D23:F23) -> 5 | H23: =VLOOKUP(A23,#REF!,5,0) -> #REF! | I23: =SUM(#REF!) -> #REF! | J23: =SUMIF(#REF!,'MEDIÇÃO 39'!A23,#REF!) -> #REF! | K23: =I23+J23 -> #REF! | L23: =G23-K23 -> #REF! | M23: =ROUND(I23*H23,2) -> #REF! | N23: =ROUND(J23*H23,2) -> #REF! | O23: =ROUND(M23+N23,2) -> #REF! | P23: =ROUND((G23*H23)-O23,2) -> #REF! | Q23: =IFERROR(ROUND(O23/(G23*H23),2),0) -> 0
A24: 2.7 | B24: EXECUÇÃO DE BASE ENGASTADA COM TUBO DE CONCRETO PARA POSTES DE ATÉ 10M DE ALTURA | C24: UN | D24: 100 | G24: =SUM(D24:F24) -> 100 | H24: =VLOOKUP(A24,#REF!,5,0) -> #REF! | I24: =SUM(#REF!) -> #REF! | J24: =SUMIF(#REF!,'MEDIÇÃO 39'!A24,#REF!) -> #REF! | K24: =I24+J24 -> #REF! | L24: =G24-K24 -> #REF! | M24: =ROUND(I24*H24,2) -> #REF! | N24: =ROUND(J24*H24,2) -> #REF! | O24: =ROUND(M24+N24,2) -> #REF! | P24: =ROUND((G24*H24)-O24,2) -> #REF! | Q24: =IFERROR(ROUND(O24/(G24*H24),2),0) -> 0
A25: 2.8 | B25: EXECUÇÃO DE BASE ENGASTADA COM TUBO DE CONCRETO PARA POSTES DE 11M ATÉ 15M DE ALTURA | C25: UN | D25: 25 | E25: 20 | G25: =SUM(D25:F25) -> 45 | H25: =VLOOKUP(A25,#REF!,5,0) -> #REF! | I25: =SUM(#REF!) -> #REF! | J25: =SUMIF(#REF!,'MEDIÇÃO 39'!A25,#REF!) -> #REF! | K25: =I25+J25 -> #REF! | L25: =G25-K25 -> #REF! | M25: =ROUND(I25*H25,2) -> #REF! | N25: =ROUND(J25*H25,2) -> #REF! | O25: =ROUND(M25+N25,2) -> #REF! | P25: =ROUND((G25*H25)-O25,2) -> #REF! | Q25: =IFERROR(ROUND(O25/(G25*H25),2),0) -> 0
A26: 2.9 | B26: FECHAMENTO DE CAVA | C26: UN | D26: 25 | G26: =SUM(D26:F26) -> 25 | H26: =VLOOKUP(A26,#REF!,5,0) -> #REF! | I26: =SUM(#REF!) -> #REF! | J26: =SUMIF(#REF!,'MEDIÇÃO 39'!A26,#REF!) -> #REF! | K26: =I26+J26 -> #REF! | L26: =G26-K26 -> #REF! | M26: =ROUND(I26*H26,2) -> #REF! | N26: =ROUND(J26*H26,2) -> #REF! | O26: =ROUND(M26+N26,2) -> #REF! | P26: =ROUND((G26*H26)-O26,2) -> #REF! | Q26: =IFERROR(ROUND(O26/(G26*H26),2),0) -> 0
A27: 2.10 | B27: IDENTIFICAÇÃO DE ILUMINAÇÃO COM PLAQUETA DE ALUMÍNIO | C27: UN | D27: 1756 | G27: =SUM(D27:F27) -> 1756 | H27: =VLOOKUP(A27,#REF!,5,0) -> #REF! | I27: =SUM(#REF!) -> #REF! | J27: =SUMIF(#REF!,'MEDIÇÃO 39'!A27,#REF!) -> #REF! | K27: =I27+J27 -> #REF! | L27: =G27-K27 -> #REF! | M27: =ROUND(I27*H27,2) -> #REF! | N27: =ROUND(J27*H27,2) -> #REF! | O27: =ROUND(M27+N27,2) -> #REF! | P27: =ROUND((G27*H27)-O27,2) -> #REF! | Q27: =IFERROR(ROUND(O27/(G27*H27),2),0) -> 0
A28: 2.11 | B28: INSTALAÇÃO DE CONDUTOR PARA ATERRAMENTO | C28: M | D28: 1000 | G28: =SUM(D28:F28) -> 1000 | H28: =VLOOKUP(A28,#REF!,5,0) -> #REF! | I28: =SUM(#REF!) -> #REF! | J28: =SUMIF(#REF!,'MEDIÇÃO 39'!A28,#REF!) -> #REF! | K28: =I28+J28 -> #REF! | L28: =G28-K28 -> #REF! | M28: =ROUND(I28*H28,2) -> #REF! | N28: =ROUND(J28*H28,2) -> #REF! | O28: =ROUND(M28+N28,2) -> #REF! | P28: =ROUND((G28*H28)-O28,2) -> #REF! | Q28: =IFERROR(ROUND(O28/(G28*H28),2),0) -> 0
A29: 2.12 | B29: INSTALAÇÃO DE CAIXA DE CONCRETO PRÉ-FABRICADA COM TAMPA, DIMENSÕES DE 40X40X40CM | C29: UN | D29: 100 | G29: =SUM(D29:F29) -> 100 | H29: =VLOOKUP(A29,#REF!,5,0) -> #REF! | I29: =SUM(#REF!) -> #REF! | J29: =SUMIF(#REF!,'MEDIÇÃO 39'!A29,#REF!) -> #REF! | K29: =I29+J29 -> #REF! | L29: =G29-K29 -> #REF! | M29: =ROUND(I29*H29,2) -> #REF! | N29: =ROUND(J29*H29,2) -> #REF! | O29: =ROUND(M29+N29,2) -> #REF! | P29: =ROUND((G29*H29)-O29,2) -> #REF! | Q29: =IFERROR(ROUND(O29/(G29*H29),2),0) -> 0
A30: 2.13 | B30: INSTALAÇÃO DE CAIXA DE CONCRETO PRÉ-FABRICADA, DIMENSÕES DE 65CM | C30: UN | D30: 25 | G30: =SUM(D30:F30) -> 25 | H30: =VLOOKUP(A30,#REF!,5,0) -> #REF! | I30: =SUM(#REF!) -> #REF! | J30: =SUMIF(#REF!,'MEDIÇÃO 39'!A30,#REF!) -> #REF! | K30: =I30+J30 -> #REF! | L30: =G30-K30 -> #REF! | M30: =ROUND(I30*H30,2) -> #REF! | N30: =ROUND(J30*H30,2) -> #REF! | O30: =ROUND(M30+N30,2) -> #REF! | P30: =ROUND((G30*H30)-O30,2) -> #REF! | Q30: =IFERROR(ROUND(O30/(G30*H30),2),0) -> 0
A31: 2.14 | B31: INSTALAÇÃO DE CHAVE DE COMANDO PARA ILUMINAÇÃO PÚBLICA | C31: UN | D31: 25 | E31: 50 | G31: =SUM(D31:F31) -> 75 | H31: =VLOOKUP(A31,#REF!,5,0) -> #REF! | I31: =SUM(#REF!) -> #REF! | J31: =SUMIF(#REF!,'MEDIÇÃO 39'!A31,#REF!) -> #REF! | K31: =I31+J31 -> #REF! | L31: =G31-K31 -> #REF! | M31: =ROUND(I31*H31,2) -> #REF! | N31: =ROUND(J31*H31,2) -> #REF! | O31: =ROUND(M31+N31,2) -> #REF! | P31: =ROUND((G31*H31)-O31,2) -> #REF! | Q31: =IFERROR(ROUND(O31/(G31*H31),2),0) -> 0
A32: 2.15 | B32: INSTALAÇÃO DE CONDUTORES DE BAIXA TENSÃO AÉREOS DE BITOLA ATÉ 70 MM2 | C32: M | D32: 250 | E32: 5000 | G32: =SUM(D32:F32) -> 5250 | H32: =VLOOKUP(A32,#REF!,5,0) -> #REF! | I32: =SUM(#REF!) -> #REF! | J32: =SUMIF(#REF!,'MEDIÇÃO 39'!A32,#REF!) -> #REF! | K32: =I32+J32 -> #REF! | L32: =G32-K32 -> #REF! | M32: =ROUND(I32*H32,2) -> #REF! | N32: =ROUND(J32*H32,2) -> #REF! | O32: =ROUND(M32+N32,2) -> #REF! | P32: =ROUND((G32*H32)-O32,2) -> #REF! | Q32: =IFERROR(ROUND(O32/(G32*H32),2),0) -> 0
A33: 2.16 | B33: INSTALAÇÃO DE CONDUTORES DE BAIXA TENSÃO, EMBUTIDOS EM ELETRODUTOS OU ENTERRADOS, DE BITOLA ATÉ 70 MM2 | C33: M | D33: 250 | E33: 1000 | G33: =SUM(D33:F33) -> 1250 | H33: =VLOOKUP(A33,#REF!,5,0) -> #REF! | I33: =SUM(#REF!) -> #REF! | J33: =SUMIF(#REF!,'MEDIÇÃO 39'!A33,#REF!) -> #REF! | K33: =I33+J33 -> #REF! | L33: =G33-K33 -> #REF! | M33: =ROUND(I33*H33,2) -> #REF! | N33: =ROUND(J33*H33,2) -> #REF! | O33: =ROUND(M33+N33,2) -> #REF! | P33: =ROUND((G33*H33)-O33,2) -> #REF! | Q33: =IFERROR(ROUND(O33/(G33*H33),2),0) -> 0
A34: 2.17 | B34: INSTALAÇÃO DE CORDA LUMINOSA COM DIÂMETRO ATÉ 13MM | C34: M | D34: 20 | F34: 3300 | G34: =SUM(D34:F34) -> 3320 | H34: =VLOOKUP(A34,#REF!,5,0) -> #REF! | I34: =SUM(#REF!) -> #REF! | J34: =SUMIF(#REF!,'MEDIÇÃO 39'!A34,#REF!) -> #REF! | K34: =I34+J34 -> #REF! | L34: =G34-K34 -> #REF! | M34: =ROUND(I34*H34,2) -> #REF! | N34: =ROUND(J34*H34,2) -> #REF! | O34: =ROUND(M34+N34,2) -> #REF! | P34: =ROUND((G34*H34)-O34,2) -> #REF! | Q34: =IFERROR(ROUND(O34/(G34*H34),2),0) -> 0
A35: 2.18 | B35: INSTALAÇÃO DE CORDÃO COM 100 MICRO LÂMPADAS | C35: UN | D35: 65 | G35: =SUM(D35:F35) -> 65 | H35: =VLOOKUP(A35,#REF!,5,0) -> #REF! | I35: =SUM(#REF!) -> #REF! | J35: =SUMIF(#REF!,'MEDIÇÃO 39'!A35,#REF!) -> #REF! | K35: =I35+J35 -> #REF! | L35: =G35-K35 -> #REF! | M35: =ROUND(I35*H35,2) -> #REF! | N35: =ROUND(J35*H35,2) -> #REF! | O35: =ROUND(M35+N35,2) -> #REF! | P35: =ROUND((G35*H35)-O35,2) -> #REF! | Q35: =IFERROR(ROUND(O35/(G35*H35),2),0) -> 0
A36: 2.19 | B36: INSTALAÇÃO DE CRUZETA PARA INSTALAÇÃO DE PROJETORES | C36: UN | D36: 5 | G36: =SUM(D36:F36) -> 5 | H36: =VLOOKUP(A36,#REF!,5,0) -> #REF! | I36: =SUM(#REF!) -> #REF! | J36: =SUMIF(#REF!,'MEDIÇÃO 39'!A36,#REF!) -> #REF! | K36: =I36+J36 -> #REF! | L36: =G36-K36 -> #REF! | M36: =ROUND(I36*H36,2) -> #REF! | N36: =ROUND(J36*H36,2) -> #REF! | O36: =ROUND(M36+N36,2) -> #REF! | P36: =ROUND((G36*H36)-O36,2) -> #REF! | Q36: =IFERROR(ROUND(O36/(G36*H36),2),0) -> 0
A37: 2.20 | B37: INSTALAÇÃO DE ESTRUTURA DE MT (15KV) | C37: UN | D37: 2 | G37: =SUM(D37:F37) -> 2 | H37: =VLOOKUP(A37,#REF!,5,0) -> #REF! | I37: =SUM(#REF!) -> #REF! | J37: =SUMIF(#REF!,'MEDIÇÃO 39'!A37,#REF!) -> #REF! | K37: =I37+J37 -> #REF! | L37: =G37-K37 -> #REF! | M37: =ROUND(I37*H37,2) -> #REF! | N37: =ROUND(J37*H37,2) -> #REF! | O37: =ROUND(M37+N37,2) -> #REF! | P37: =ROUND((G37*H37)-O37,2) -> #REF! | Q37: =IFERROR(ROUND(O37/(G37*H37),2),0) -> 0
A38: 2.21 | B38: INSTALAÇÃO DE FIGURA LUMINOSA EM POSTES, BRAÇOS EXISTENTES OU PAREDE DE EDIFICAÇÃO | C38: M | D38: 32.5 | G38: =SUM(D38:F38) -> 32.5 | H38: =VLOOKUP(A38,#REF!,5,0) -> #REF! | I38: =SUM(#REF!) -> #REF! | J38: =SUMIF(#REF!,'MEDIÇÃO 39'!A38,#REF!) -> #REF! | K38: =I38+J38 -> #REF! | L38: =G38-K38 -> #REF! | M38: =ROUND(I38*H38,2) -> #REF! | N38: =ROUND(J38*H38,2) -> #REF! | O38: =ROUND(M38+N38,2) -> #REF! | P38: =ROUND((G38*H38)-O38,2) -> #REF! | Q38: =IFERROR(ROUND(O38/(G38*H38),2),0) -> 0
A39: 2.22 | B39: INSTALAÇÃO DE GRADE DE PROTEÇÃO PARA PROJETOR | C39: PÇ | D39: 3.5 | G39: =SUM(D39:F39) -> 3.5 | H39: =VLOOKUP(A39,#REF!,5,0) -> #REF! | I39: =SUM(#REF!) -> #REF! | J39: =SUMIF(#REF!,'MEDIÇÃO 39'!A39,#REF!) -> #REF! | K39: =I39+J39 -> #REF! | L39: =G39-K39 -> #REF! | M39: =ROUND(I39*H39,2) -> #REF! | N39: =ROUND(J39*H39,2) -> #REF! | O39: =ROUND(M39+N39,2) -> #REF! | P39: =ROUND((G39*H39)-O39,2) -> #REF! | Q39: =IFERROR(ROUND(O39/(G39*H39),2),0) -> 0
A40: 2.23 | B40: INSTALAÇÃO DE LUMINÁRIA EM BRAÇO DE ATÉ 1,5 METRO | C40: UN | D40: 659 | E40: 75 | F40: 300 | G40: =SUM(D40:F40) -> 1034 | H40: =VLOOKUP(A40,#REF!,5,0) -> #REF! | I40: =SUM(#REF!) -> #REF! | J40: =SUMIF(#REF!,'MEDIÇÃO 39'!A40,#REF!) -> #REF! | K40: =I40+J40 -> #REF! | L40: =G40-K40 -> #REF! | M40: =ROUND(I40*H40,2) -> #REF! | N40: =ROUND(J40*H40,2) -> #REF! | O40: =ROUND(M40+N40,2) -> #REF! | P40: =ROUND((G40*H40)-O40,2) -> #REF! | Q40: =IFERROR(ROUND(O40/(G40*H40),2),0) -> 0
A41: 2.24 | B41: INSTALAÇÃO DE LUMINÁRIA EM BRAÇO SUPERIOR A 1,5 METRO | C41: UN | D41: 1098 | E41: 75 | G41: =SUM(D41:F41) -> 1173 | H41: =VLOOKUP(A41,#REF!,5,0) -> #REF! | I41: =SUM(#REF!) -> #REF! | J41: =SUMIF(#REF!,'MEDIÇÃO 39'!A41,#REF!) -> #REF! | K41: =I41+J41 -> #REF! | L41: =G41-K41 -> #REF! | M41: =ROUND(I41*H41,2) -> #REF! | N41: =ROUND(J41*H41,2) -> #REF! | O41: =ROUND(M41+N41,2) -> #REF! | P41: =ROUND((G41*H41)-O41,2) -> #REF! | Q41: =IFERROR(ROUND(O41/(G41*H41),2),0) -> 0
...
